Workbook

Sheet الرموز
A1: الجهاز (Device) | B1: الماركة (Brand) | C1: الموديلات (Models) | D1: الرمز (Code) | E1: المعنى (Meaning) | F1: الأسباب المذكورة في المصادر (Causes) | G1: من يتعامل معه (Who) | H1: درجة التوثيق (Verification) | I1: المصادر (Sources) | J1: حالة الصفحة (Page status) | K1: ملاحظات (Notes) | L1: هل تكمل القيادة؟ (Keep driving?)
A2: مكيف سبليت (Split AC) | B2: جري (Gree) | C2: لم تُحدَّد بعد | D2: E1 | E2: حماية الضغط العالي | F2: ملفات متسخة، انسداد، شحنة فريون زائدة | G2: المستخدم أولاً ثم فني | H2: رسمي (الشركة) | I2: جري الرسمي، Arlington، Japan Electronics | J2: لم تُكتب
A3: مكيف سبليت (Split AC) | B3: جري (Gree) | C3: لم تُحدَّد بعد | D3: E2 | E3: حماية من التجمد في وضع التبريد | F3: فلتر مسدود، ملف تبريد متسخ، فريون ناقص، مروحة معطلة | G3: المستخدم أولاً ثم فني | H3: مصدران متفقان | I3: Arlington، Japan Electronics | J3: لم تُكتب
A4: مكيف سبليت (Split AC) | B4: جري (Gree) | C4: لم تُحدَّد بعد | D4: E3 | E4: حماية الضغط المنخفض | F4: فلاتر أو ملفات متسخة، تسريب فريون | G4: المستخدم أولاً ثم فني | H4: رسمي (الشركة) | I4: جري الرسمي، Arlington | J4: لم تُكتب
A5: مكيف سبليت (Split AC) | B5: جري (Gree) | C5: لم تُحدَّد بعد | D5: E4 | E5: حماية من ارتفاع حرارة طرد الضاغط | F5: فلاتر متسخة، انسداد في المكثف أو المبخر | G5: المستخدم أولاً ثم فني | H5: مصدران متفقان | I5: Arlington، Japan Electronics | J5: لم تُكتب
A6: مكيف سبليت (Split AC) | B6: جري (Gree) | C6: لم تُحدَّد بعد | D6: E5 | E6: حماية من ارتفاع التيار | F6: جهد الكهرباء مرتفع أو غير مستقر | G6: فني | H6: رسمي (الشركة) | I6: جري الرسمي، Arlington، Japan Electronics | J6: لم تُكتب
A7: مكيف سبليت (Split AC) | B7: جري (Gree) | C7: لم تُحدَّد بعد | D7: E6 | E7: انقطاع التواصل بين الوحدة الداخلية والخارجية | F7: سلك خاطئ أو موصول من قطعتين، أطراف مرتخية، كيبل تالف، تلف لوحة | G7: المستخدم أولاً ثم فني | H7: رسمي (الشركة) | I7: دليل E6 الرسمي، Arlington، Japan Electronics، قائمة Scribd | J7: منشورة (نموذج) | K7: في أنظمة 380 فولت قد يظهر عند انعكاس ترتيب الأطوار
A8: مكيف سبليت (Split AC) | B8: جري (Gree) | C8: لم تُحدَّد بعد | D8: E7 | E8: تعارض الأوضاع | F8: الوحدة الداخلية والخارجية مضبوطتان على وضعين مختلفين | G8: المستخدم أولاً ثم فني | H8: رسمي (الشركة) | I8: جري الرسمي، Arlington | J8: لم تُكتب
A9: مكيف سبليت (Split AC) | B9: جري (Gree) | C9: لم تُحدَّد بعد | D9: E8 | E9: حماية من ارتفاع الحرارة، مرتبطة بمروحة الوحدة الداخلية أو لوحتها | F9: محرك المروحة الداخلية معطل، لوحة داخلية معيبة | G9: فني | H9: مصدران متفقان | I9: Arlington، Japan Electronics | J9: لم تُكتب | K9: المصدران يتفقان على القطعة ويختلفان في تسمية الرمز
A10: مكيف سبليت (Split AC) | B10: جري (Gree) | C10: لم تُحدَّد بعد | D10: E9 | E10: حماية متعلقة بالماء | F10: مضخة التصريف لا تعمل وامتلاء حوض الماء (Arlington)، أو مفتاح تدفق الماء (Japan Electronics) | G10: فني | H10: المصادر متعارضة | I10: Arlington، Japan Electronics | J10: لم تُكتب | K10: يحتاج كتيب صيانة للحسم
A11: مكيف سبليت (Split AC) | B11: جري (Gree) | C11: لم تُحدَّد بعد | D11: EE | E11: عطل ذاكرة اللوحة (EEPROM) | F11: تلف شريحة الذاكرة في لوحة الوحدة الخارجية | G11: فني | H11: مصدران متفقان | I11: Arlington، Japan Electronics، قائمة Scribd | J11: لم تُكتب
A12: مكيف سبليت (Split AC) | B12: جري (Gree) | C12: لم تُحدَّد بعد | D12: EH | E12: عطل السخان المساعد | F12: ريليه عالق، جهد غير مستقر، سلك مرتخٍ، رطوبة أو صدأ | G12: فني | H12: مصدر واحد | I12: Arlington | J12: لم تُكتب
A13: مكيف سبليت (Split AC) | B13: جري (Gree) | C13: لم تُحدَّد بعد | D13: EU | E13: انخفاض التردد بسبب سخونة وحدة الطاقة IPM | G13: فني | H13: مصدر واحد | I13: Japan Electronics | J13: لم تُكتب
A14: مكيف سبليت (Split AC) | B14: جري (Gree) | C14: لم تُحدَّد بعد | D14: F0 | E14: نقص الفريون | G14: فني | H14: مصدران متفقان | I14: Arlington، Japan Electronics | J14: لم تُكتب | K14: Arlington يسميه أيضاً وضع استرجاع الفريون
A15: مكيف سبليت (Split AC) | B15: جري (Gree) | C15: لم تُحدَّد بعد | D15: F1 | E15: عطل حساس حرارة الغرفة في الوحدة الداخلية | F15: تلف الحساس أو انفصاله | G15: فني | H15: رسمي (الشركة) | I15: جري الرسمي، Japan Electronics | J15: لم تُكتب | K15: Arlington يذكر معنى مختلفاً (حساس ماسورة المبخر)
A16: مكيف سبليت (Split AC) | B16: جري (Gree) | C16: لم تُحدَّد بعد | D16: F2 | E16: عطل حساس المبخر في الوحدة الداخلية | F16: تلف الحساس أو سلكه | G16: فني | H16: رسمي (الشركة) | I16: جري الرسمي، Japan Electronics | J16: لم تُكتب | K16: Arlington يذكر معنى مختلفاً
A17: مكيف سبليت (Split AC) | B17: جري (Gree) | C17: لم تُحدَّد بعد | D17: F3 | E17: عطل حساس حرارة الجو في الوحدة الخارجية | F17: تلف الحساس أو انفصاله | G17: فني | H17: رسمي (الشركة) | I17: جري الرسمي، Arlington، Japan Electronics | J17: لم تُكتب
A18: مكيف سبليت (Split AC) | B18: جري (Gree) | C18: لم تُحدَّد بعد | D18: F4 | E18: عطل حساس ماسورة الوحدة الخارجية | F18: تلف الحساس أو تحركه من مكانه | G18: فني | H18: رسمي (الشركة) | I18: جري الرسمي، Japan Electronics | J18: لم تُكتب | K18: Arlington يذكر معنى مختلفاً
A19: مكيف سبليت (Split AC) | B19: جري (Gree) | C19: لم تُحدَّد بعد | D19: F5 | E19: عطل حساس حرارة الطرد | F19: تلف الحساس أو سلكه | G19: فني | H19: رسمي (الشركة) | I19: جري الرسمي، Japan Electronics | J19: لم تُكتب | K19: Arlington يذكر معنى مختلفاً
A20: مكيف سبليت (Split AC) | B20: جري (Gree) | C20: لم تُحدَّد بعد | D20: F6 | E20: غير محسوم | F20: حساس منتصف ماسورة الوحدة الخارجية (Arlington)، أو حد الحمل الزائد وانخفاض التردد (Japan Electronics) | G20: فني | H20: المصادر متعارضة | I20: Arlington، Japan Electronics | J20: لم تُكتب | K20: يحتاج كتيب صيانة للحسم
A21: مكيف سبليت (Split AC) | B21: جري (Gree) | C21: لم تُحدَّد بعد | D21: F7 | E21: عملية إرجاع الزيت | G21: حالة طبيعية | H21: مصدر واحد | I21: Arlington | J21: لم تُكتب | K21: المصدر يصفه كتشغيل طبيعي
A22: مكيف سبليت (Split AC) | B22: جري (Gree) | C22: لم تُحدَّد بعد | D22: F8 | E22: حد حماية من الحمل الزائد أو التيار الزائد مع انخفاض التردد | G22: فني | H22: المصادر متعارضة | I22: Arlington، Japan Electronics | J22: لم تُكتب | K22: الصياغتان متقاربتان وغير متطابقتين
A23: مكيف سبليت (Split AC) | B23: جري (Gree) | C23: لم تُحدَّد بعد | D23: F9 | E23: انخفاض التردد بسبب ارتفاع حرارة الطرد | G23: فني | H23: مصدران متفقان | I23: Arlington، Japan Electronics، قائمة Scribd | J23: لم تُكتب
A24: مكيف سبليت (Split AC) | B24: جري (Gree) | C24: لم تُحدَّد بعد | D24: FA | E24: انخفاض التردد بسبب ارتفاع حرارة الماسورة | G24: فني | H24: مصدران متفقان | I24: Arlington، Japan Electronics | J24: لم تُكتب
A25: مكيف سبليت (Split AC) | B25: جري (Gree) | C25: لم تُحدَّد بعد | D25: FC | E25: مشكلة في الباب المنزلق | G25: فني | H25: مصدر واحد | I25: Japan Electronics | J25: لم تُكتب
A26: مكيف سبليت (Split AC) | B26: جري (Gree) | C26: لم تُحدَّد بعد | D26: FE | E26: عطل حساس الحمل الزائد للضاغط | G26: فني | H26: مصدر واحد | I26: Japan Electronics | J26: لم تُكتب
A27: مكيف سبليت (Split AC) | B27: جري (Gree) | C27: لم تُحدَّد بعد | D27: FH | E27: انخفاض التردد بسبب حد منع التجمد | G27: المستخدم أولاً ثم فني | H27: مصدر واحد | I27: Japan Electronics | J27: لم تُكتب | K27: Arlington يضع المعنى نفسه تحت الرمز Fb
A28: مكيف سبليت (Split AC) | B28: جري (Gree) | C28: لم تُحدَّد بعد | D28: H0 | E28: انخفاض التردد بسبب ارتفاع الحرارة في وضع التدفئة | G28: فني | H28: مصدر واحد | I28: Japan Electronics | J28: لم تُكتب
A29: مكيف سبليت (Split AC) | B29: جري (Gree) | C29: لم تُحدَّد بعد | D29: H1 | E29: وضع إذابة الصقيع | F29: يظهر في التدفئة أثناء إذابة الثلج عن الوحدة الخارجية | G29: حالة طبيعية | H29: رسمي (الشركة) | I29: جري الرسمي، Arlington، Japan Electronics | J29: لم تُكتب | K29: يُفحص فقط إن طال أو تكرر كثيراً
A30: مكيف سبليت (Split AC) | B30: جري (Gree) | C30: لم تُحدَّد بعد | D30: H2 | E30: حماية الترسيب الكهروستاتيكي | G30: فني | H30: مصدر واحد | I30: Japan Electronics | J30: لم تُكتب
A31: مكيف سبليت (Split AC) | B31: جري (Gree) | C31: لم تُحدَّد بعد | D31: H3 | E31: حماية الحمل الزائد للضاغط | F31: حمل زائد على الضاغط | G31: فني | H31: مصدران متفقان | I31: Arlington، Japan Electronics | J31: لم تُكتب
A32: مكيف سبليت (Split AC) | B32: جري (Gree) | C32: لم تُحدَّد بعد | D32: H4 | E32: حمل زائد على النظام أو ارتفاع حرارة الماسورة | F32: انسداد المبادل الحراري | G32: المستخدم أولاً ثم فني | H32: مصدران متفقان | I32: Arlington، Japan Electronics | J32: لم تُكتب
A33: مكيف سبليت (Split AC) | B33: جري (Gree) | C33: لم تُحدَّد بعد | D33: H5 | E33: حماية وحدة الطاقة IPM | F33: مشاكل جهد أو حرارة | G33: فني | H33: رسمي (الشركة) | I33: جري الرسمي، Arlington، Japan Electronics | J33: لم تُكتب
A34: مكيف سبليت (Split AC) | B34: جري (Gree) | C34: لم تُحدَّد بعد | D34: H6 | E34: محرك المروحة الداخلية لا يرسل إشارة | F34: مروحة داخلية معاقة أو محركها معطل | G34: فني | H34: مصدران متفقان | I34: Arlington، Japan Electronics، قائمة Scribd | J34: لم تُكتب
A35: مكيف سبليت (Split AC) | B35: جري (Gree) | C35: لم تُحدَّد بعد | D35: H7 | E35: فقدان تزامن الضاغط | F35: مشكلة في محرك الضاغط | G35: فني | H35: مصدران متفقان | I35: Arlington، Japan Electronics | J35: لم تُكتب
A36: مكيف سبليت (Split AC) | B36: جري (Gree) | C36: لم تُحدَّد بعد | D36: HC | E36: حماية دائرة تصحيح معامل القدرة PFC | G36: فني | H36: مصدران متفقان | I36: Arlington، Japan Electronics | J36: لم تُكتب
A37: مكيف سبليت (Split AC) | B37: جري (Gree) | C37: لم تُحدَّد بعد | D37: HE | E37: حماية من فقدان مغناطيسية الضاغط | G37: فني | H37: مصدر واحد | I37: Japan Electronics | J37: لم تُكتب
A38: مكيف سبليت (Split AC) | B38: جري (Gree) | C38: لم تُحدَّد بعد | D38: L3 | E38: عطل محرك المروحة الخارجية | F38: المروحة لا تدور أو تغذيتها ضعيفة | G38: فني | H38: مصدران متفقان | I38: Arlington، Japan Electronics | J38: لم تُكتب
A39: مكيف سبليت (Split AC) | B39: جري (Gree) | C39: لم تُحدَّد بعد | D39: L9 | E39: حماية الطاقة | F39: ارتفاع مفاجئ كبير في الكهرباء | G39: فني | H39: رسمي (الشركة) | I39: جري الرسمي، Arlington | J39: لم تُكتب
A40: مكيف سبليت (Split AC) | B40: جري (Gree) | C40: لم تُحدَّد بعد | D40: LC | E40: فشل إقلاع الضاغط | G40: فني | H40: مصدران متفقان | I40: Arlington، Japan Electronics | J40: لم تُكتب
...

Sheet خطة الماركات
A1: المرحلة | B1: الجهاز | C1: الماركة | D1: عدد الرموز المدخلة | E1: منها رسمي | F1: الصفحات المنشورة | G1: الحالة | H1: ملاحظة
A2: 1 | B2: مكيف سبليت (Split AC) | C2: جري (Gree) | D2: =COUNTIFS('الرموز'!$A:$A,B2,'الرموز'!$B:$B,C2) | E2: =COUNTIFS('الرموز'!$A:$A,B2,'الرموز'!$B:$B,C2,'الرموز'!$H:$H,"رسمي (الشركة)") | F2: =COUNTIFS('الرموز'!$A:$A,B2,'الرموز'!$B:$B,C2,'الرموز'!$J:$J,"منشورة*") | G2: =IF(D2=0,"لم يبدأ","بدأ")
A3: 1 | B3: مكيف سبليت (Split AC) | C3: ميديا (Midea) | D3: =COUNTIFS('الرموز'!$A:$A,B3,'الرموز'!$B:$B,C3) | E3: =COUNTIFS('الرموز'!$A:$A,B3,'الرموز'!$B:$B,C3,'الرموز'!$H:$H,"رسمي (الشركة)") | F3: =COUNTIFS('الرموز'!$A:$A,B3,'الرموز'!$B:$B,C3,'الرموز'!$J:$J,"منشورة*") | G3: =IF(D3=0,"لم يبدأ","بدأ") | H3: بلا مصدر رسمي، والرموز تختلف بين السلاسل
A4: 1 | B4: مكيف سبليت (Split AC) | C4: إل جي (LG) | D4: =COUNTIFS('الرموز'!$A:$A,B4,'الرموز'!$B:$B,C4) | E4: =COUNTIFS('الرموز'!$A:$A,B4,'الرموز'!$B:$B,C4,'الرموز'!$H:$H,"رسمي (الشركة)") | F4: =COUNTIFS('الرموز'!$A:$A,B4,'الرموز'!$B:$B,C4,'الرموز'!$J:$J,"منشورة*") | G4: =IF(D4=0,"لم يبدأ","بدأ")
A5: 1 | B5: مكيف سبليت (Split AC) | C5: سامسونج (Samsung) | D5: =COUNTIFS('الرموز'!$A:$A,B5,'الرموز'!$B:$B,C5) | E5: =COUNTIFS('الرموز'!$A:$A,B5,'الرموز'!$B:$B,C5,'الرموز'!$H:$H,"رسمي (الشركة)") | F5: =COUNTIFS('الرموز'!$A:$A,B5,'الرموز'!$B:$B,C5,'الرموز'!$J:$J,"منشورة*") | G5: =IF(D5=0,"لم يبدأ","بدأ")
A6: 1 | B6: مكيف سبليت (Split AC) | C6: هاير (Haier) | D6: =COUNTIFS('الرموز'!$A:$A,B6,'الرموز'!$B:$B,C6) | E6: =COUNTIFS('الرموز'!$A:$A,B6,'الرموز'!$B:$B,C6,'الرموز'!$H:$H,"رسمي (الشركة)") | F6: =COUNTIFS('الرموز'!$A:$A,B6,'الرموز'!$B:$B,C6,'الرموز'!$J:$J,"منشورة*") | G6: =IF(D6=0,"لم يبدأ","بدأ")
A7: 1 | B7: مكيف سبليت (Split AC) | C7: تي سي إل (TCL) | D7: =COUNTIFS('الرموز'!$A:$A,B7,'الرموز'!$B:$B,C7) | E7: =COUNTIFS('الرموز'!$A:$A,B7,'الرموز'!$B:$B,C7,'الرموز'!$H:$H,"رسمي (الشركة)") | F7: =COUNTIFS('الرموز'!$A:$A,B7,'الرموز'!$B:$B,C7,'الرموز'!$J:$J,"منشورة*") | G7: =IF(D7=0,"لم يبدأ","بدأ") | H7: مصدر واحد، ومصدر آخر يخالفه كلياً
A8: 1 | B8: مكيف سبليت (Split AC) | C8: هايسنس (Hisense) | D8: =COUNTIFS('الرموز'!$A:$A,B8,'الرموز'!$B:$B,C8) | E8: =COUNTIFS('الرموز'!$A:$A,B8,'الرموز'!$B:$B,C8,'الرموز'!$H:$H,"رسمي (الشركة)") | F8: =COUNTIFS('الرموز'!$A:$A,B8,'الرموز'!$B:$B,C8,'الرموز'!$J:$J,"منشورة*") | G8: =IF(D8=0,"لم يبدأ","بدأ")
A9: 1 | B9: مكيف سبليت (Split AC) | C9: جنرال (O General / Fujitsu General) | D9: =COUNTIFS('الرموز'!$A:$A,B9,'الرموز'!$B:$B,C9) | E9: =COUNTIFS('الرموز'!$A:$A,B9,'الرموز'!$B:$B,C9,'الرموز'!$H:$H,"رسمي (الشركة)") | F9: =COUNTIFS('الرموز'!$A:$A,B9,'الرموز'!$B:$B,C9,'الرموز'!$J:$J,"منشورة*") | G9: =IF(D9=0,"لم يبدأ","بدأ")
A10: 1 | B10: مكيف سبليت (Split AC) | C10: الزامل (Zamil) | D10: =COUNTIFS('الرموز'!$A:$A,B10,'الرموز'!$B:$B,C10) | E10: =COUNTIFS('الرموز'!$A:$A,B10,'الرموز'!$B:$B,C10,'الرموز'!$H:$H,"رسمي (الشركة)") | F10: =COUNTIFS('الرموز'!$A:$A,B10,'الرموز'!$B:$B,C10,'الرموز'!$J:$J,"منشورة*") | G10: =IF(D10=0,"لم يبدأ","بدأ") | H10: لم أجد مصدراً موثوقاً. يحتاج كتيب الصيانة أو صفحة الشركة
A11: 1 | B11: مكيف سبليت (Split AC) | C11: كاريير (Carrier) | D11: =COUNTIFS('الرموز'!$A:$A,B11,'الرموز'!$B:$B,C11) | E11: =COUNTIFS('الرموز'!$A:$A,B11,'الرموز'!$B:$B,C11,'الرموز'!$H:$H,"رسمي (الشركة)") | F11: =COUNTIFS('الرموز'!$A:$A,B11,'الرموز'!$B:$B,C11,'الرموز'!$J:$J,"منشورة*") | G11: =IF(D11=0,"لم يبدأ","بدأ")
A12: 1 | B12: مكيف سبليت (Split AC) | C12: يورك (York) | D12: =COUNTIFS('الرموز'!$A:$A,B12,'الرموز'!$B:$B,C12) | E12: =COUNTIFS('الرموز'!$A:$A,B12,'الرموز'!$B:$B,C12,'الرموز'!$H:$H,"رسمي (الشركة)") | F12: =COUNTIFS('الرموز'!$A:$A,B12,'الرموز'!$B:$B,C12,'الرموز'!$J:$J,"منشورة*") | G12: =IF(D12=0,"لم يبدأ","بدأ") | H12: لم أجد مصدراً موثوقاً. يحتاج كتيب الصيانة أو صفحة الشركة
A13: 1 | B13: مكيف سبليت (Split AC) | C13: دايكن (Daikin) | D13: =COUNTIFS('الرموز'!$A:$A,B13,'الرموز'!$B:$B,C13) | E13: =COUNTIFS('الرموز'!$A:$A,B13,'الرموز'!$B:$B,C13,'الرموز'!$H:$H,"رسمي (الشركة)") | F13: =COUNTIFS('الرموز'!$A:$A,B13,'الرموز'!$B:$B,C13,'الرموز'!$J:$J,"منشورة*") | G13: =IF(D13=0,"لم يبدأ","بدأ")
A14: 1 | B14: مكيف سبليت (Split AC) | C14: ميتسوبيشي (Mitsubishi) | D14: =COUNTIFS('الرموز'!$A:$A,B14,'الرموز'!$B:$B,C14) | E14: =COUNTIFS('الرموز'!$A:$A,B14,'الرموز'!$B:$B,C14,'الرموز'!$H:$H,"رسمي (الشركة)") | F14: =COUNTIFS('الرموز'!$A:$A,B14,'الرموز'!$B:$B,C14,'الرموز'!$J:$J,"منشورة*") | G14: =IF(D14=0,"لم يبدأ","بدأ")
A15: 1 | B15: مكيف سبليت (Split AC) | C15: باناسونيك (Panasonic) | D15: =COUNTIFS('الرموز'!$A:$A,B15,'الرموز'!$B:$B,C15) | E15: =COUNTIFS('الرموز'!$A:$A,B15,'الرموز'!$B:$B,C15,'الرموز'!$H:$H,"رسمي (الشركة)") | F15: =COUNTIFS('الرموز'!$A:$A,B15,'الرموز'!$B:$B,C15,'الرموز'!$J:$J,"منشورة*") | G15: =IF(D15=0,"لم يبدأ","بدأ")
A16: 1 | B16: تكييف مركزي (Central / VRF AC) | C16: سامسونج (Samsung) | D16: =COUNTIFS('الرموز'!$A:$A,B16,'الرموز'!$B:$B,C16) | E16: =COUNTIFS('الرموز'!$A:$A,B16,'الرموز'!$B:$B,C16,'الرموز'!$H:$H,"رسمي (الشركة)") | F16: =COUNTIFS('الرموز'!$A:$A,B16,'الرموز'!$B:$B,C16,'الرموز'!$J:$J,"منشورة*") | G16: =IF(D16=0,"لم يبدأ","بدأ") | H16: فُصلت عن السبليت بحسب نص المعنى (وحدات MCU، ضواغط متعددة). الفصل تقديري ويحتاج مراجعة فني
A17: 1 | B17: تكييف مركزي (Central / VRF AC) | C17: دايكن (Daikin) | D17: =COUNTIFS('الرموز'!$A:$A,B17,'الرموز'!$B:$B,C17) | E17: =COUNTIFS('الرموز'!$A:$A,B17,'الرموز'!$B:$B,C17,'الرموز'!$H:$H,"رسمي (الشركة)") | F17: =COUNTIFS('الرموز'!$A:$A,B17,'الرموز'!$B:$B,C17,'الرموز'!$J:$J,"منشورة*") | G17: =IF(D17=0,"لم يبدأ","بدأ") | H17: فُصلت عن السبليت بحسب نص المعنى (ملحقات، شحن تلقائي، متحكم مركزي). الفصل تقديري
A18: 1 | B18: تكييف مركزي (Central / VRF AC) | C18: ميتسوبيشي (Mitsubishi) | D18: =COUNTIFS('الرموز'!$A:$A,B18,'الرموز'!$B:$B,C18) | E18: =COUNTIFS('الرموز'!$A:$A,B18,'الرموز'!$B:$B,C18,'الرموز'!$H:$H,"رسمي (الشركة)") | F18: =COUNTIFS('الرموز'!$A:$A,B18,'الرموز'!$B:$B,C18,'الرموز'!$J:$J,"منشورة*") | G18: =IF(D18=0,"لم يبدأ","بدأ") | H18: الرموز الرقمية لأنظمة City Multi
A19: 2 | B19: غسالة ملابس (Washing machine) | C19: سامسونج (Samsung) | D19: =COUNTIFS('الرموز'!$A:$A,B19,'الرموز'!$B:$B,C19) | E19: =COUNTIFS('الرموز'!$A:$A,B19,'الرموز'!$B:$B,C19,'الرموز'!$H:$H,"رسمي (الشركة)") | F19: =COUNTIFS('الرموز'!$A:$A,B19,'الرموز'!$B:$B,C19,'الرموز'!$J:$J,"منشورة*") | G19: =IF(D19=0,"لم يبدأ","بدأ")
A20: 2 | B20: غسالة ملابس (Washing machine) | C20: إل جي (LG) | D20: =COUNTIFS('الرموز'!$A:$A,B20,'الرموز'!$B:$B,C20) | E20: =COUNTIFS('الرموز'!$A:$A,B20,'الرموز'!$B:$B,C20,'الرموز'!$H:$H,"رسمي (الشركة)") | F20: =COUNTIFS('الرموز'!$A:$A,B20,'الرموز'!$B:$B,C20,'الرموز'!$J:$J,"منشورة*") | G20: =IF(D20=0,"لم يبدأ","بدأ")
A21: 2 | B21: غسالة ملابس (Washing machine) | C21: بوش (Bosch) | D21: =COUNTIFS('الرموز'!$A:$A,B21,'الرموز'!$B:$B,C21) | E21: =COUNTIFS('الرموز'!$A:$A,B21,'الرموز'!$B:$B,C21,'الرموز'!$H:$H,"رسمي (الشركة)") | F21: =COUNTIFS('الرموز'!$A:$A,B21,'الرموز'!$B:$B,C21,'الرموز'!$J:$J,"منشورة*") | G21: =IF(D21=0,"لم يبدأ","بدأ")
A22: 2 | B22: غسالة ملابس (Washing machine) | C22: سيمنس (Siemens) | D22: =COUNTIFS('الرموز'!$A:$A,B22,'الرموز'!$B:$B,C22) | E22: =COUNTIFS('الرموز'!$A:$A,B22,'الرموز'!$B:$B,C22,'الرموز'!$H:$H,"رسمي (الشركة)") | F22: =COUNTIFS('الرموز'!$A:$A,B22,'الرموز'!$B:$B,C22,'الرموز'!$J:$J,"منشورة*") | G22: =IF(D22=0,"لم يبدأ","بدأ")
A23: 2 | B23: غسالة ملابس (Washing machine) | C23: ويرلبول (Whirlpool) | D23: =COUNTIFS('الرموز'!$A:$A,B23,'الرموز'!$B:$B,C23) | E23: =COUNTIFS('الرموز'!$A:$A,B23,'الرموز'!$B:$B,C23,'الرموز'!$H:$H,"رسمي (الشركة)") | F23: =COUNTIFS('الرموز'!$A:$A,B23,'الرموز'!$B:$B,C23,'الرموز'!$J:$J,"منشورة*") | G23: =IF(D23=0,"لم يبدأ","بدأ")
A24: 2 | B24: غسالة ملابس (Washing machine) | C24: بيكو (Beko) | D24: =COUNTIFS('الرموز'!$A:$A,B24,'الرموز'!$B:$B,C24) | E24: =COUNTIFS('الرموز'!$A:$A,B24,'الرموز'!$B:$B,C24,'الرموز'!$H:$H,"رسمي (الشركة)") | F24: =COUNTIFS('الرموز'!$A:$A,B24,'الرموز'!$B:$B,C24,'الرموز'!$J:$J,"منشورة*") | G24: =IF(D24=0,"لم يبدأ","بدأ")
A25: 2 | B25: غسالة ملابس (Washing machine) | C25: أريستون (Ariston) | D25: =COUNTIFS('الرموز'!$A:$A,B25,'الرموز'!$B:$B,C25) | E25: =COUNTIFS('الرموز'!$A:$A,B25,'الرموز'!$B:$B,C25,'الرموز'!$H:$H,"رسمي (الشركة)") | F25: =COUNTIFS('الرموز'!$A:$A,B25,'الرموز'!$B:$B,C25,'الرموز'!$J:$J,"منشورة*") | G25: =IF(D25=0,"لم يبدأ","بدأ") | H25: المصدر عن Hotpoint الشقيقة
A26: 2 | B26: غسالة ملابس (Washing machine) | C26: توشيبا (Toshiba) | D26: =COUNTIFS('الرموز'!$A:$A,B26,'الرموز'!$B:$B,C26) | E26: =COUNTIFS('الرموز'!$A:$A,B26,'الرموز'!$B:$B,C26,'الرموز'!$H:$H,"رسمي (الشركة)") | F26: =COUNTIFS('الرموز'!$A:$A,B26,'الرموز'!$B:$B,C26,'الرموز'!$J:$J,"منشورة*") | G26: =IF(D26=0,"لم يبدأ","بدأ")
A27: 2 | B27: غسالة ملابس (Washing machine) | C27: هاير (Haier) | D27: =COUNTIFS('الرموز'!$A:$A,B27,'الرموز'!$B:$B,C27) | E27: =COUNTIFS('الرموز'!$A:$A,B27,'الرموز'!$B:$B,C27,'الرموز'!$H:$H,"رسمي (الشركة)") | F27: =COUNTIFS('الرموز'!$A:$A,B27,'الرموز'!$B:$B,C27,'الرموز'!$J:$J,"منشورة*") | G27: =IF(D27=0,"لم يبدأ","بدأ")
A28: 2 | B28: غسالة ملابس (Washing machine) | C28: ميديا (Midea) | D28: =COUNTIFS('الرموز'!$A:$A,B28,'الرموز'!$B:$B,C28) | E28: =COUNTIFS('الرموز'!$A:$A,B28,'الرموز'!$B:$B,C28,'الرموز'!$H:$H,"رسمي (الشركة)") | F28: =COUNTIFS('الرموز'!$A:$A,B28,'الرموز'!$B:$B,C28,'الرموز'!$J:$J,"منشورة*") | G28: =IF(D28=0,"لم يبدأ","بدأ")
A29: 3 | B29: غسالة صحون (Dishwasher) | C29: بوش (Bosch) | D29: =COUNTIFS('الرموز'!$A:$A,B29,'الرموز'!$B:$B,C29) | E29: =COUNTIFS('الرموز'!$A:$A,B29,'الرموز'!$B:$B,C29,'الرموز'!$H:$H,"رسمي (الشركة)") | F29: =COUNTIFS('الرموز'!$A:$A,B29,'الرموز'!$B:$B,C29,'الرموز'!$J:$J,"منشورة*") | G29: =IF(D29=0,"لم يبدأ","بدأ")
A30: 3 | B30: غسالة صحون (Dishwasher) | C30: سيمنس (Siemens) | D30: =COUNTIFS('الرموز'!$A:$A,B30,'الرموز'!$B:$B,C30) | E30: =COUNTIFS('الرموز'!$A:$A,B30,'الرموز'!$B:$B,C30,'الرموز'!$H:$H,"رسمي (الشركة)") | F30: =COUNTIFS('الرموز'!$A:$A,B30,'الرموز'!$B:$B,C30,'الرموز'!$J:$J,"منشورة*") | G30: =IF(D30=0,"لم يبدأ","بدأ") | H30: لم أجد مصدراً موثوقاً. يحتاج كتيب الصيانة أو صفحة الشركة
A31: 3 | B31: غسالة صحون (Dishwasher) | C31: سامسونج (Samsung) | D31: =COUNTIFS('الرموز'!$A:$A,B31,'الرموز'!$B:$B,C31) | E31: =COUNTIFS('الرموز'!$A:$A,B31,'الرموز'!$B:$B,C31,'الرموز'!$H:$H,"رسمي (الشركة)") | F31: =COUNTIFS('الرموز'!$A:$A,B31,'الرموز'!$B:$B,C31,'الرموز'!$J:$J,"منشورة*") | G31: =IF(D31=0,"لم يبدأ","بدأ")
A32: 3 | B32: غسالة صحون (Dishwasher) | C32: إل جي (LG) | D32: =COUNTIFS('الرموز'!$A:$A,B32,'الرموز'!$B:$B,C32) | E32: =COUNTIFS('الرموز'!$A:$A,B32,'الرموز'!$B:$B,C32,'الرموز'!$H:$H,"رسمي (الشركة)") | F32: =COUNTIFS('الرموز'!$A:$A,B32,'الرموز'!$B:$B,C32,'الرموز'!$J:$J,"منشورة*") | G32: =IF(D32=0,"لم يبدأ","بدأ")
A33: 3 | B33: غسالة صحون (Dishwasher) | C33: بيكو (Beko) | D33: =COUNTIFS('الرموز'!$A:$A,B33,'الرموز'!$B:$B,C33) | E33: =COUNTIFS('الرموز'!$A:$A,B33,'الرموز'!$B:$B,C33,'الرموز'!$H:$H,"رسمي (الشركة)") | F33: =COUNTIFS('الرموز'!$A:$A,B33,'الرموز'!$B:$B,C33,'الرموز'!$J:$J,"منشورة*") | G33: =IF(D33=0,"لم يبدأ","بدأ")
A34: 3 | B34: غسالة صحون (Dishwasher) | C34: ويرلبول (Whirlpool) | D34: =COUNTIFS('الرموز'!$A:$A,B34,'الرموز'!$B:$B,C34) | E34: =COUNTIFS('الرموز'!$A:$A,B34,'الرموز'!$B:$B,C34,'الرموز'!$H:$H,"رسمي (الشركة)") | F34: =COUNTIFS('الرموز'!$A:$A,B34,'الرموز'!$B:$B,C34,'الرموز'!$J:$J,"منشورة*") | G34: =IF(D34=0,"لم يبدأ","بدأ")
A35: 3 | B35: غسالة صحون (Dishwasher) | C35: أريستون (Ariston) | D35: =COUNTIFS('الرموز'!$A:$A,B35,'الرموز'!$B:$B,C35) | E35: =COUNTIFS('الرموز'!$A:$A,B35,'الرموز'!$B:$B,C35,'الرموز'!$H:$H,"رسمي (الشركة)") | F35: =COUNTIFS('الرموز'!$A:$A,B35,'الرموز'!$B:$B,C35,'الرموز'!$J:$J,"منشورة*") | G35: =IF(D35=0,"لم يبدأ","بدأ") | H35: المصدر عن Hotpoint الشقيقة
A36: 3 | B36: نشافة ملابس (Dryer) | C36: سامسونج (Samsung) | D36: =COUNTIFS('الرموز'!$A:$A,B36,'الرموز'!$B:$B,C36) | E36: =COUNTIFS('الرموز'!$A:$A,B36,'الرموز'!$B:$B,C36,'الرموز'!$H:$H,"رسمي (الشركة)") | F36: =COUNTIFS('الرموز'!$A:$A,B36,'الرموز'!$B:$B,C36,'الرموز'!$J:$J,"منشورة*") | G36: =IF(D36=0,"لم يبدأ","بدأ")
A37: 3 | B37: نشافة ملابس (Dryer) | C37: إل جي (LG) | D37: =COUNTIFS('الرموز'!$A:$A,B37,'الرموز'!$B:$B,C37) | E37: =COUNTIFS('الرموز'!$A:$A,B37,'الرموز'!$B:$B,C37,'الرموز'!$H:$H,"رسمي (الشركة)") | F37: =COUNTIFS('الرموز'!$A:$A,B37,'الرموز'!$B:$B,C37,'الرموز'!$J:$J,"منشورة*") | G37: =IF(D37=0,"لم يبدأ","بدأ")
A38: 3 | B38: نشافة ملابس (Dryer) | C38: بوش (Bosch) | D38: =COUNTIFS('الرموز'!$A:$A,B38,'الرموز'!$B:$B,C38) | E38: =COUNTIFS('الرموز'!$A:$A,B38,'الرموز'!$B:$B,C38,'الرموز'!$H:$H,"رسمي (الشركة)") | F38: =COUNTIFS('الرموز'!$A:$A,B38,'الرموز'!$B:$B,C38,'الرموز'!$J:$J,"منشورة*") | G38: =IF(D38=0,"لم يبدأ","بدأ")
A39: 3 | B39: نشافة ملابس (Dryer) | C39: بيكو (Beko) | D39: =COUNTIFS('الرموز'!$A:$A,B39,'الرموز'!$B:$B,C39) | E39: =COUNTIFS('الرموز'!$A:$A,B39,'الرموز'!$B:$B,C39,'الرموز'!$H:$H,"رسمي (الشركة)") | F39: =COUNTIFS('الرموز'!$A:$A,B39,'الرموز'!$B:$B,C39,'الرموز'!$J:$J,"منشورة*") | G39: =IF(D39=0,"لم يبدأ","بدأ") | H39: لم أجد مصدراً موثوقاً. يحتاج كتيب الصيانة أو صفحة الشركة
A40: 3 | B40: نشافة ملابس (Dryer) | C40: ويرلبول (Whirlpool) | D40: =COUNTIFS('الرموز'!$A:$A,B40,'الرموز'!$B:$B,C40) | E40: =COUNTIFS('الرموز'!$A:$A,B40,'الرموز'!$B:$B,C40,'الرموز'!$H:$H,"رسمي (الشركة)") | F40: =COUNTIFS('الرموز'!$A:$A,B40,'الرموز'!$B:$B,C40,'الرموز'!$J:$J,"منشورة*") | G40: =IF(D40=0,"لم يبدأ","بدأ") | H40: صفحة ويرلبول الرسمية تسرد الرموز دون معانيها في صفحة واحدة. كل رمز له صفحة مستقلة
...

Sheet اقرأني
A1: كيف تضيف رمزاً جديداً | B1: أضف صفاً في ورقة «الرموز». الأعمدة من «الجهاز» إلى «المصادر» مطلوبة. الأعمدة الثلاثة «من يتعامل معه» و«درجة التوثيق» و«حالة الصفحة» فيها قوائم اختيار.
A2: كتابة الجهاز والماركة | B2: اكتبهما مطابقين حرفياً لما في ورقة «خطة الماركات»، لأن الأعداد هناك تُحسب بالمطابقة. اسم الجهاز واسم الماركة يُكتبان بالعربية ثم الإنجليزية بين قوسين، مثل: مكيف سبليت (Split AC) وجري (Gree).
A3: الموديلات | B3: الرمز نفسه قد يختلف معناه بين سلاسل الماركة الواحدة، وهذا واضح جداً في ميديا. اكتب السلسلة أو الموديلات التي ينطبق عليها الصف. الصفوف الحالية لم تُحدَّد موديلاتها بعد.
A5: درجة التوثيق
A6: رسمي (الشركة) | B6: المعنى مأخوذ من صفحة الشركة المصنّعة نفسها. يُنشر بثقة.
A7: مصدران متفقان | B7: مصدران مستقلان يتفقان على المعنى. يُنشر مع ذكر المصادر.
A8: مصدر واحد | B8: مصدر واحد فقط. لا يُنشر قبل تأكيده من كتيب صيانة أو فني.
A9: المصادر متعارضة | B9: المصادر تعطي معاني مختلفة. لا يُنشر حتى يُحسم من كتيب الصيانة للموديل.
A11: هل تكمل القيادة؟ | B11: عمود للسيارات فقط. حيث لم يذكر المصدر الحكم صراحةً استُنتج من نص الرسالة وتصنيفها، فهو إرشاد أولي وليس بديلاً عن كتيّب المالك.
A12: حدود هذه النسخة | B12: الأسباب منقولة من المصادر كما هي. الخانة الفارغة تعني أن المصدر لم يذكر سبباً، ولم تُملأ بالتخمين. عمود «من يتعامل معه» تقدير أولي يحتاج مراجعة فني تكييف.
A14: المصادر
A15: جري الرسمي | B15: https://www.greecomfort.com/news-and-events/understanding-gree-mini-split-error-codes/
A16: دليل E6 الرسمي | B16: https://www.greecomfort.com/news-and-events/gree-mini-split-e6-error-code-troubleshooting-guide/
A17: Arlington | B17: https://arlingtonairconditioningheating.com/gree-air-conditioner-error-codes/
A18: Japan Electronics | B18: https://japanelectronics.com.pk/blogs/all/error-code-list-of-gree-ac-in-2024
A19: قائمة Scribd | B19: https://www.scribd.com/document/717173518/Error-Codes
A20: Arlington (ميديا) | B20: https://arlingtonairconditioningheating.com/midea-air-conditioner-error-codes/
A21: RemoveAndReplace | B21: https://removeandreplace.com/?p=15924
A22: Mytour | B22: https://mytour.vn/en/blog/bai-viet/compilation-of-midea-air-conditioner-error-codes.html
A23: LG الرسمي (US) | B23: https://www.lg.com/us/support/help-library/lg-air-conditioner-guide-to-error-codes--20155047719306
A24: LG الرسمي (Africa) | B24: https://www.lg.com/africa/support/product-help/CT20080061-20155402833925
A25: Arlington (LG) | B25: https://www.arlingtonairconditioningheating.com/lg-air-conditioner-troubleshooting/
A26: TechFaultFix | B26: https://techfaultfix.com/air-conditioners/lg
... A162: تاريخ الجمع | B162: 2026-10-06
